(dp1
S'output'
p2
S'<type \'exceptions.RuntimeError\'> Failure to connect, tried 5 times:\nTraceback (most recent call last):\n  File "/var/www/web2py/gluon/packages/dal/pydal/base.py", line 458, in __init__\n    self._adapter = adapter(**kwargs)\n  File "/var/www/web2py/gluon/packages/dal/pydal/adapters/postgres.py", line 27, in __call__\n    return AdapterMeta.__call__(cls, *args, **kwargs)\n  File "/var/www/web2py/gluon/packages/dal/pydal/adapters/__init__.py", line 40, in __call__\n    obj = super(AdapterMeta, cls).__call__(*args, **kwargs)\n  File "/var/www/web2py/gluon/packages/dal/pydal/adapters/postgres.py", line 48, in __init__\n    driver_args, adapter_args, do_connect, after_connection)\n  File "/var/www/web2py/gluon/packages/dal/pydal/adapters/base.py", line 373, in __init__\n    super(SQLAdapter, self).__init__(*args, **kwargs)\n  File "/var/www/web2py/gluon/packages/dal/pydal/adapters/base.py", line 53, in __init__\n    self.reconnect()\n  File "/var/www/web2py/gluon/packages/dal/pydal/connection.py", line 148, in reconnect\n    self.connection = self.connector()\n  File "/var/www/web2py/gluon/packages/dal/pydal/adapters/postgres.py", line 102, in connector\n    return self.driver.connect(**self.driver_args)\n  File "/usr/lib64/python2.7/site-packages/psycopg2/__init__.py", line 164, in connect\n    conn = _connect(dsn, connection_factory=connection_factory, async=async)\nOperationalError: could not connect to server: Connection refused\n\tIs the server running on host "10.140.48.102" and accepting\n\tTCP/IP connections on port 5440?\n\n'
p3
sS'layer'
p4
S'/var/www/web2py/applications/lotylda_mng/models/db.py'
p5
sS'code'
p6
S'# -*- coding: utf-8 -*-\n\nif False:  # this block helps eclipse\n    from gluon.sql import *  # repeat for all models\n    from gluon import *\n\nfrom gluon import current\nfrom gluon.utils import *\nfrom gluon.tools import Auth\nimport psycopg2\nimport psycopg2.extras\nfrom gluon.tools import Mail\n\nis_migrate = False\n\nDBSettings = {}\nDBSettings[\'DBhost\']= \'10.140.48.102\'\nDBSettings[\'DBname\'] = \'lotylda_mng\'\nDBSettings[\'DBschema\'] = \'engine\'\nDBSettings[\'DBport\'] = \'5440\'\nDBSettings[\'DBuser\'] = \'lotylda_admin\'\nDBSettings[\'DBpassword\'] = \'lotylda\'\n\ncurrent.db_name = DBSettings[\'DBname\']\ncurrent.dbData_settings = DBSettings\n\ndb = DAL(\'postgres://\'+DBSettings[\'DBuser\']+\':\'+DBSettings[\'DBpassword\']+\'@\'+DBSettings[\'DBhost\']+\':\'+DBSettings[\'DBport\']+\'/\'+DBSettings[\'DBname\'],migrate=is_migrate, fake_migrate=False)\n\nauth = Auth(db)\nauth.settings.extra_fields[\'auth_user\']= [\n  Field(\'user_id\', type=\'string\', length=32, compute=lambda r: md5_hash(r[\'email\'])),\n  Field(\'active\', type=\'boolean\',compute=lambda s: 0)\n]\nauth.define_tables(username=True)\nauth.settings.registration_requires_approval = True\nauth.settings.remember_me_form = False\nauth.settings.allow_basic_login = True\n\nauth.messages.reset_password = "<html>Hi %(first_name)s, <br />you have been invited to Lotylda application. <br /> \\\n            Your username is: <b>%(username)s</b>  <br /> \\\n            Use link below to set your new password. <br /><a href=\\"http://" + request.env.http_host +     URL(r=request,c=\'default\',f=\'user\',args=[\'reset_password\']) +     "/?key=%(key)s \\">Set password</a></html>"\n            \n#auth.settings.actions_disabled=[\'register\']\nmail = auth.settings.mailer\n\nmail.settings.server = \'mail.optisolutions.cz:25\'\nmail.settings.sender = \'lotylda@optisolutions.cz\'\nmail.settings.login = \'opti_service@optisolutions.cz:5V[ebu&Bx4oL\'\n\n\ncurrent.db = db\n#current.connection = connection\ncurrent.auth = auth \n\n#current.project_url = "https://portal.lotylda.com"\ncurrent.project_url = "http://10.140.48.102"'
p7
sS'snapshot'
p8
(dp9
sS'traceback'
p10
S'Traceback (most recent call last):\n  File "/var/www/web2py/gluon/restricted.py", line 224, in restricted\n    exec(ccode, environment)\n  File "/var/www/web2py/applications/lotylda_mng/models/db.py", line 27, in <module>\n    db = DAL(\'postgres://\'+DBSettings[\'DBuser\']+\':\'+DBSettings[\'DBpassword\']+\'@\'+DBSettings[\'DBhost\']+\':\'+DBSettings[\'DBport\']+\'/\'+DBSettings[\'DBname\'],migrate=is_migrate, fake_migrate=False)\n  File "/var/www/web2py/gluon/packages/dal/pydal/base.py", line 173, in __call__\n    obj = super(MetaDAL, cls).__call__(*args, **kwargs)\n  File "/var/www/web2py/gluon/packages/dal/pydal/base.py", line 478, in __init__\n    "Failure to connect, tried %d times:\\n%s" % (attempts, tb)\nRuntimeError: Failure to connect, tried 5 times:\nTraceback (most recent call last):\n  File "/var/www/web2py/gluon/packages/dal/pydal/base.py", line 458, in __init__\n    self._adapter = adapter(**kwargs)\n  File "/var/www/web2py/gluon/packages/dal/pydal/adapters/postgres.py", line 27, in __call__\n    return AdapterMeta.__call__(cls, *args, **kwargs)\n  File "/var/www/web2py/gluon/packages/dal/pydal/adapters/__init__.py", line 40, in __call__\n    obj = super(AdapterMeta, cls).__call__(*args, **kwargs)\n  File "/var/www/web2py/gluon/packages/dal/pydal/adapters/postgres.py", line 48, in __init__\n    driver_args, adapter_args, do_connect, after_connection)\n  File "/var/www/web2py/gluon/packages/dal/pydal/adapters/base.py", line 373, in __init__\n    super(SQLAdapter, self).__init__(*args, **kwargs)\n  File "/var/www/web2py/gluon/packages/dal/pydal/adapters/base.py", line 53, in __init__\n    self.reconnect()\n  File "/var/www/web2py/gluon/packages/dal/pydal/connection.py", line 148, in reconnect\n    self.connection = self.connector()\n  File "/var/www/web2py/gluon/packages/dal/pydal/adapters/postgres.py", line 102, in connector\n    return self.driver.connect(**self.driver_args)\n  File "/usr/lib64/python2.7/site-packages/psycopg2/__init__.py", line 164, in connect\n    conn = _connect(dsn, connection_factory=connection_factory, async=async)\nOperationalError: could not connect to server: Connection refused\n\tIs the server running on host "10.140.48.102" and accepting\n\tTCP/IP connections on port 5440?\n\n\n'
p11
s.